<?xml version="1.0" encoding="utf-8"?>
<robot xmlns:xacro="http://www.ros.org/wiki/xacro" name="hand">

  <!-- ──────────── macro arguments ──────────── -->
  <xacro:macro name="hand"
               params="
                   connected_to:=''
                   description_pkg:='panda_description'
                   ns:=''
                   rpy:='0 0 0'
                   xyz:='0 0 0'
                   safety_distance:=0
                   use_sim_time:='false'
                   simulation_controllers_config_file:=''">

    <!-- convenience -->
    <xacro:property name="pkg" value="package://${description_pkg}"/>

    <!-- ───── optional attachment joint (hand to last arm link) ───── -->
    <xacro:unless value="${connected_to == ''}">
      <joint name="${ns}_hand_joint" type="fixed">
        <parent link="${connected_to}"/>
        <child  link="${ns}_hand"/>
        <origin xyz="${xyz}" rpy="${rpy}"/>
      </joint>
    </xacro:unless>

    <!-- ═══════════════════ HAND BASE ═══════════════════ -->
    <link name="${ns}_hand">
      <inertial>
        <origin xyz="0 0 0.05" rpy="0 0 0"/>
        <mass value="0.10"/>
        <inertia ixx="4.5e-4" ixy="0" ixz="0"
                 iyy="4.5e-4" iyz="0"
                 izz="8.0e-4"/>
      </inertial>

      <visual>
        <geometry>
          <mesh filename="$(find ${description_pkg})/meshes/visual/hand.dae"/>
        </geometry>
      </visual>

    <collision>
      <origin xyz="0 0 0" rpy="0 0 0"/>
        <geometry><mesh filename="$(find ${description_pkg})/meshes/collision/hand.stl"/></geometry>
    </collision>
    </link>

    <!-- TCP frame (for MoveIt, etc.) -->
    <link  name="${ns}_hand_tcp"/>
    <joint name="${ns}_hand_tcp_joint" type="fixed">
      <parent link="${ns}_hand"/>
      <child  link="${ns}_hand_tcp"/>
      <origin xyz="0 0 0.1034" rpy="0 0 0"/>
    </joint>

    <!-- ═══════════════════ LEFT FINGER ═══════════════════ -->
    <link name="${ns}_leftfinger">
      <inertial>
        <mass value="0.01"/>
        <inertia ixx="1e-5" ixy="0" ixz="0"
                 iyy="1e-5" iyz="0"
                 izz="1e-5"/>
      </inertial>
      <visual>
        <geometry><mesh filename="$(find ${description_pkg})/meshes/visual/cylinder_finger.dae"/></geometry>
      </visual>
      <collision>
 <!-- alternative simple finger cylinder collision 
            <origin xyz="0 0.0091 0.03" rpy="0 0 0"/>
        <geometry>  <cylinder radius="0.01" length="0.05"/> </geometry> -->

  <!-- alternative simple finger box collision 
            <origin xyz="0 0.0091 0.03" rpy="0 0 0"/>
        <geometry>  <box size=".016 0.018 0.05"/> </geometry>-->

  <!-- stl collision  -->
  <geometry><mesh filename="$(find ${description_pkg})/meshes/collision/cylinder_finger.stl"/></geometry> 

                  <surface>
            <friction>
              <ode>
                <mu>2.80</mu>           <!-- Static friction -->
                <mu2>2.80</mu2>         <!-- Sliding friction -->
              </ode>
            </friction>
            <bounce>
              <restitution_coefficient>0.0</restitution_coefficient>
              <threshold>1.0</threshold>
            </bounce>
            <contact>
              <ode>
                <kp>100000</kp>       <!-- Contact stiffness -->
                <kd>2000</kd>           <!-- Contact damping -->
                <min_depth>0.00005</min_depth>
              </ode>
            </contact>
          </surface>
      </collision>
    </link>

    <!-- ═══════════════════ RIGHT FINGER (mirrored) ═══════════════════ -->
    <link name="${ns}_rightfinger">
      <inertial>
        <mass value="0.01"/>
        <inertia ixx="1e-5" ixy="0" ixz="0"
                 iyy="1e-5" iyz="0"
                 izz="1e-5"/>
      </inertial>
      <visual>
        <origin rpy="0 0 ${pi}"/>
        <geometry><mesh filename="$(find ${description_pkg})/meshes/visual/cylinder_finger.dae"/></geometry>
      </visual>
      <collision>

<!-- alternative simple finger cylinder collision 
            <origin xyz="0 -0.0091 0.03" rpy="0 0 ${pi}"/>
        <geometry>  <cylinder radius="0.01" length="0.05"/> </geometry> -->


 <!-- alternative simple finger box collision 
            <origin xyz="0 -0.0091 0.03" rpy="0 0 ${pi}"/>
        <geometry>  <box size=".016 0.018 0.05"/> </geometry> -->

<!-- stl collision -->
        <origin rpy="0 0 ${pi}"/>
        <geometry><mesh filename="$(find ${description_pkg})/meshes/collision/cylinder_finger.stl"/></geometry> 
                  <surface>
            <friction>
              <ode>
                <mu>2.80</mu>           <!-- Static friction -->
                <mu2>2.80</mu2>         <!-- Sliding friction -->
              </ode>
            </friction>
            <bounce>
              <restitution_coefficient>0.0</restitution_coefficient>
              <threshold>1.0</threshold>
            </bounce>
            <contact>
              <ode>
                <kp>100000</kp>       <!-- Contact stiffness -->
                <kd>2000</kd>           <!-- Contact damping -->
                <min_depth>0.00005</min_depth>
              </ode>
            </contact>
          </surface>
      </collision>
    </link>

    <!-- ═══════════════════ PRISMATIC JOINTS ═══════════════════ -->
    <joint name="${ns}_finger_joint1" type="prismatic">
      <parent link="${ns}_hand"/>
      <child  link="${ns}_leftfinger"/>
      <origin xyz="0 0 0.0584" rpy="0 0 0"/>
      <axis   xyz="0 1 0"/>
      <limit  effort="120" lower="0.00" upper="0.04" velocity="1.3"/>
      <dynamics damping="120.0" friction="0"/>
    </joint>

    <joint name="${ns}_finger_joint2" type="prismatic">
      <parent link="${ns}_hand"/>
      <child  link="${ns}_rightfinger"/>
      <origin xyz="0 0 0.0584" rpy="0 0 0"/>
      <axis   xyz="0 -1 0"/>
      <limit  effort="120" lower="0.00" upper="0.04" velocity="1.3"/>
      <dynamics damping="120.0" friction="0"/>
    </joint>

    <!-- ═══════════════════ TRANSMISSIONS (ros2-control) ═══════════════════ -->
    <transmission name="${ns}_finger_trans">
      <type>transmission_interface/SimpleTransmission</type>
      <joint name="${ns}_finger_joint1">
        <hardwareInterface>hardware_interface/Position</hardwareInterface>
      </joint>
      <actuator name="${ns}_finger_actuator">
        <hardwareInterface>hardware_interface/Position</hardwareInterface>
        <mechanicalReduction>1</mechanicalReduction>
      </actuator>
    </transmission>
  <!-- identical, fully-actuated transmission for finger_joint2 -->
  <transmission name="${ns}_finger_trans2">
    <type>transmission_interface/SimpleTransmission</type>
    <joint name="${ns}_finger_joint2">
      <hardwareInterface>hardware_interface/Position</hardwareInterface>
    </joint>
    <actuator name="${ns}_finger_actuator2">
      <hardwareInterface>hardware_interface/Position</hardwareInterface>
      <mechanicalReduction>1</mechanicalReduction>
    </actuator>
  </transmission>

  </xacro:macro>
</robot>
